// *** Error Handling in Promises ***
const promise_1 = new Promise((resolve, reject) => {
  reject(new Error('Error from promise 1 ğŸ˜”'))
})

promise_1
  .then(
    (result) => {
      console.log(`ResultğŸ¥°: `, result)
    },
    (err) => {
      console.log(`ErrorğŸ˜¤: `, err.message)
    }
  )

 // Alternative method using catch
promise_1
  .then(result => console.log(`ResultğŸ¥°: `, result))
  .catch(err   => console.log(`ErrorğŸ˜¤: ` , err.message))
